[=== Module anaconda/3 loaded ===]
[=== Module cudatoolkit/12.6.0 loaded ===]
/home/mila/s/sparsha.mishra/scratch/budgeted_CL_llava/lib/python3.10/site-packages/timm/models/layers/__init__.py:48: FutureWarning: Importing from timm.models.layers is deprecated, please import via timm.layers
  warnings.warn(f"Importing from {__name__} is deprecated, please import via timm.layers", FutureWarning)
INFO:datasets:PyTorch version 2.2.1+cu118 available.
[W CUDAAllocatorConfig.h:30] Warning: expandable_segments not supported on this platform (function operator())
/home/mila/s/sparsha.mishra/scratch/budgeted_CL_llava/lib/python3.10/site-packages/huggingface_hub/file_download.py:795: FutureWarning: `resume_download` is deprecated and will be removed in version 1.0.0. Downloads always resume when possible. If you want to force a new download, use `force_download=True`.
  warnings.warn(
Loading checkpoint shards:   0%|          | 0/3 [00:00<?, ?it/s]Loading checkpoint shards:  33%|███▎      | 1/3 [00:01<00:03,  1.56s/it]Loading checkpoint shards:  67%|██████▋   | 2/3 [00:06<00:03,  3.28s/it]Loading checkpoint shards: 100%|██████████| 3/3 [00:08<00:00,  2.71s/it]Loading checkpoint shards: 100%|██████████| 3/3 [00:08<00:00,  2.69s/it]
Traceback (most recent call last):
  File "/home/mila/s/sparsha.mishra/scratch/budgeted_CL_llava/lib/python3.10/site-packages/urllib3/connectionpool.py", line 534, in _make_request
    response = conn.getresponse()
  File "/home/mila/s/sparsha.mishra/scratch/budgeted_CL_llava/lib/python3.10/site-packages/urllib3/connection.py", line 516, in getresponse
    httplib_response = super().getresponse()
  File "/home/mila/s/sparsha.mishra/scratch/budgeted_CL_llava/lib/python3.10/http/client.py", line 1375, in getresponse
    response.begin()
  File "/home/mila/s/sparsha.mishra/scratch/budgeted_CL_llava/lib/python3.10/http/client.py", line 318, in begin
    version, status, reason = self._read_status()
  File "/home/mila/s/sparsha.mishra/scratch/budgeted_CL_llava/lib/python3.10/http/client.py", line 279, in _read_status
    line = str(self.fp.readline(_MAXLINE + 1), "iso-8859-1")
  File "/home/mila/s/sparsha.mishra/scratch/budgeted_CL_llava/lib/python3.10/socket.py", line 717, in readinto
    return self._sock.recv_into(b)
  File "/home/mila/s/sparsha.mishra/scratch/budgeted_CL_llava/lib/python3.10/ssl.py", line 1307, in recv_into
    return self.read(nbytes, buffer)
  File "/home/mila/s/sparsha.mishra/scratch/budgeted_CL_llava/lib/python3.10/ssl.py", line 1163, in read
    return self._sslobj.read(len, buffer)
TimeoutError: The read operation timed out

The above exception was the direct cause of the following exception:

Traceback (most recent call last):
  File "/home/mila/s/sparsha.mishra/scratch/budgeted_CL_llava/lib/python3.10/site-packages/requests/adapters.py", line 667, in send
    resp = conn.urlopen(
  File "/home/mila/s/sparsha.mishra/scratch/budgeted_CL_llava/lib/python3.10/site-packages/urllib3/connectionpool.py", line 841, in urlopen
    retries = retries.increment(
  File "/home/mila/s/sparsha.mishra/scratch/budgeted_CL_llava/lib/python3.10/site-packages/urllib3/util/retry.py", line 474, in increment
    raise reraise(type(error), error, _stacktrace)
  File "/home/mila/s/sparsha.mishra/scratch/budgeted_CL_llava/lib/python3.10/site-packages/urllib3/util/util.py", line 39, in reraise
    raise value
  File "/home/mila/s/sparsha.mishra/scratch/budgeted_CL_llava/lib/python3.10/site-packages/urllib3/connectionpool.py", line 787, in urlopen
    response = self._make_request(
  File "/home/mila/s/sparsha.mishra/scratch/budgeted_CL_llava/lib/python3.10/site-packages/urllib3/connectionpool.py", line 536, in _make_request
    self._raise_timeout(err=e, url=url, timeout_value=read_timeout)
  File "/home/mila/s/sparsha.mishra/scratch/budgeted_CL_llava/lib/python3.10/site-packages/urllib3/connectionpool.py", line 367, in _raise_timeout
    raise ReadTimeoutError(
urllib3.exceptions.ReadTimeoutError: HTTPSConnectionPool(host='huggingface.co', port=443): Read timed out. (read timeout=10)

During handling of the above exception, another exception occurred:

Traceback (most recent call last):
  File "/network/scratch/s/sparsha.mishra/smh/budgeted_CL_LLAVA/main_new_llava_trainer.py", line 382, in <module>
    main()
  File "/network/scratch/s/sparsha.mishra/smh/budgeted_CL_LLAVA/main_new_llava_trainer.py", line 88, in main
    model, tokenizer, data_args = get_VLMmodel(model_args, training_args, bnb_model_from_pretrained_args, data_args)
  File "/network/scratch/s/sparsha.mishra/smh/budgeted_CL_LLAVA/utils/train_utils.py", line 700, in get_VLMmodel
    model.get_model().initialize_vision_modules(
  File "/network/scratch/s/sparsha.mishra/smh/budgeted_CL_LLAVA/models/llava/llava_arch.py", line 70, in initialize_vision_modules
    vision_tower.load_model()
  File "/network/scratch/s/sparsha.mishra/smh/budgeted_CL_LLAVA/models/llava/multimodal_encoder/clip_encoder.py", line 30, in load_model
    self.vision_tower = CLIPVisionModel.from_pretrained(self.vision_tower_name, device_map=device_map)
  File "/home/mila/s/sparsha.mishra/scratch/budgeted_CL_llava/lib/python3.10/site-packages/transformers/modeling_utils.py", line 3370, in from_pretrained
    if not has_file(pretrained_model_name_or_path, safe_weights_name, **has_file_kwargs):
  File "/home/mila/s/sparsha.mishra/scratch/budgeted_CL_llava/lib/python3.10/site-packages/transformers/utils/hub.py", line 627, in has_file
    r = requests.head(url, headers=headers, allow_redirects=False, proxies=proxies, timeout=10)
  File "/home/mila/s/sparsha.mishra/scratch/budgeted_CL_llava/lib/python3.10/site-packages/requests/api.py", line 100, in head
    return request("head", url, **kwargs)
  File "/home/mila/s/sparsha.mishra/scratch/budgeted_CL_llava/lib/python3.10/site-packages/requests/api.py", line 59, in request
    return session.request(method=method, url=url, **kwargs)
  File "/home/mila/s/sparsha.mishra/scratch/budgeted_CL_llava/lib/python3.10/site-packages/requests/sessions.py", line 589, in request
    resp = self.send(prep, **send_kwargs)
  File "/home/mila/s/sparsha.mishra/scratch/budgeted_CL_llava/lib/python3.10/site-packages/requests/sessions.py", line 703, in send
    r = adapter.send(request, **kwargs)
  File "/home/mila/s/sparsha.mishra/scratch/budgeted_CL_llava/lib/python3.10/site-packages/requests/adapters.py", line 713, in send
    raise ReadTimeout(e, request=request)
requests.exceptions.ReadTimeout: HTTPSConnectionPool(host='huggingface.co', port=443): Read timed out. (read timeout=10)
